Workbook

Sheet Dashboard
A1: DASHBOARD — VISÃO DO MÊS
A3: Mês analisado: | B3: =Config!B6 -> 46136 | C3: (edite em Config!B6 para mudar o mês)
A4: Primeiro dia | B4: =DATE(YEAR(B3),MONTH(B3),1) -> 46113 | C4: Último dia | D4: =EOMONTH(B3,0) -> 46142
A6: Resumo do Mês
A7: Indicador | D7: Planejado | E7: Realizado | F7: Saldo | G7: % Plan.
A8: Renda (entradas) | D8: ='Orçamento Mensal'!B9 -> 8700 | E8: =SUMIFS('Lançamentos'!C:C,'Lançamentos'!B:B,"Receita",'Lançamentos'!A:A,">="&$B$4,'Lançamentos'!A:A,"<="&$D$4) -> 0 | F8: =E8-D8 -> -8700 | G8: =IF(D8=0,0,E8/D8) -> 0
A9: Gastos totais | D9: ='Orçamento Mensal'!B18+'Orçamento Mensal'!B29+'Orçamento Mensal'!B38+'Orçamento Mensal'!B47+'Orçamento Mensal'!B57+'Orçamento Mensal'!B67+'Orçamento Mensal'!B74 -> 8155 | E9: =SUMIFS('Lançamentos'!C:C,'Lançamentos'!B:B,"Despesa",'Lançamentos'!A:A,">="&$B$4,'Lançamentos'!A:A,"<="&$D$4) -> 19 | F9: =D9-E9 -> 8136 | G9: =IF(D9=0,0,E9/D9) -> 0.002329859
A10: Sobra real do mês | D10: =D8-D9 -> 545 | E10: =E8-E9 -> -19 | F10: =E10-D10 -> -564 | G10: =IF(D10=0,0,E10/D10) -> -0.034862385
A12: Acerto do Mês — Quanto a Luana transfere pro Gustavo
A13: Luana recebeu (real) | E13: =SUMIFS('Lançamentos'!C:C,'Lançamentos'!B:B,"Receita",'Lançamentos'!A:A,">="&$B$4,'Lançamentos'!A:A,"<="&$D$4,'Lançamentos'!E:E,"Luana") -> 0
A14: (-) Luana gastou no mês | E14: =SUMIFS('Lançamentos'!C:C,'Lançamentos'!B:B,"Despesa",'Lançamentos'!A:A,">="&$B$4,'Lançamentos'!A:A,"<="&$D$4,'Lançamentos'!E:E,"Luana") -> 0
A15: (-) Reserva pessoal Luana | E15: =Config!B5 -> 0
A16: → Transferência para Gustavo | E16: =E13-E14-E15 -> 0
A17: Obs.: a reserva pessoal é o quanto ela separa pra projetos dela antes de transferir. Edite em Config!B5. Se ela pagar a fatura dela direto, cada compra já entra como gasto dela.
A19: Gastos por Pagador
A20: Pagador | C20: Gasto no mês | D20: % do total | E20: Observação
A21: Gustavo | C21: =SUMIFS('Lançamentos'!C:C,'Lançamentos'!B:B,"Despesa",'Lançamentos'!A:A,">="&$B$4,'Lançamentos'!A:A,"<="&$D$4,'Lançamentos'!E:E,"Gustavo") -> 19 | D21: =IF($E$9=0,0,C21/$E$9) -> 1
A22: Luana | C22: =SUMIFS('Lançamentos'!C:C,'Lançamentos'!B:B,"Despesa",'Lançamentos'!A:A,">="&$B$4,'Lançamentos'!A:A,"<="&$D$4,'Lançamentos'!E:E,"Luana") -> 0 | D22: =IF($E$9=0,0,C22/$E$9) -> 0
A24: Planejado × Realizado por Categoria
A25: Grupo | B25: Categoria | D25: Planejado | E25: Realizado | F25: Saldo | G25: % Consumido
A26: Fixos | B26: Financ. Caixa | D26: =VLOOKUP(B26,Config!$E$11:$F$50,2,FALSE()) -> 1910 | E26: =SUMIFS('Lançamentos'!C:C,'Lançamentos'!B:B,"Despesa",'Lançamentos'!A:A,">="&$B$4,'Lançamentos'!A:A,"<="&$D$4,'Lançamentos'!D:D,B26) -> 0 | F26: =D26-E26 -> 1910 | G26: =IF(D26=0,IF(E26=0,0,9.99),E26/D26) -> 0
A27: Fixos | B27: Financ. Vasco | D27: =VLOOKUP(B27,Config!$E$11:$F$50,2,FALSE()) -> 870 | E27: =SUMIFS('Lançamentos'!C:C,'Lançamentos'!B:B,"Despesa",'Lançamentos'!A:A,">="&$B$4,'Lançamentos'!A:A,"<="&$D$4,'Lançamentos'!D:D,B27) -> 0 | F27: =D27-E27 -> 870 | G27: =IF(D27=0,IF(E27=0,0,9.99),E27/D27) -> 0
A28: Fixos | B28: Combustível moto | D28: =VLOOKUP(B28,Config!$E$11:$F$50,2,FALSE()) -> 145 | E28: =SUMIFS('Lançamentos'!C:C,'Lançamentos'!B:B,"Despesa",'Lançamentos'!A:A,">="&$B$4,'Lançamentos'!A:A,"<="&$D$4,'Lançamentos'!D:D,B28) -> 0 | F28: =D28-E28 -> 145 | G28: =IF(D28=0,IF(E28=0,0,9.99),E28/D28) -> 0
A29: Fixos | B29: Óleo moto (provisão) | D29: =VLOOKUP(B29,Config!$E$11:$F$50,2,FALSE()) -> 75 | E29: =SUMIFS('Lançamentos'!C:C,'Lançamentos'!B:B,"Despesa",'Lançamentos'!A:A,">="&$B$4,'Lançamentos'!A:A,"<="&$D$4,'Lançamentos'!D:D,B29) -> 0 | F29: =D29-E29 -> 75 | G29: =IF(D29=0,IF(E29=0,0,9.99),E29/D29) -> 0
A30: Fixos | B30: Uber Luana | D30: =VLOOKUP(B30,Config!$E$11:$F$50,2,FALSE()) -> 200 | E30: =SUMIFS('Lançamentos'!C:C,'Lançamentos'!B:B,"Despesa",'Lançamentos'!A:A,">="&$B$4,'Lançamentos'!A:A,"<="&$D$4,'Lançamentos'!D:D,B30) -> 0 | F30: =D30-E30 -> 200 | G30: =IF(D30=0,IF(E30=0,0,9.99),E30/D30) -> 0
A31: Alimentação | B31: Supermercado | D31: =VLOOKUP(B31,Config!$E$11:$F$50,2,FALSE()) -> 800 | E31: =SUMIFS('Lançamentos'!C:C,'Lançamentos'!B:B,"Despesa",'Lançamentos'!A:A,">="&$B$4,'Lançamentos'!A:A,"<="&$D$4,'Lançamentos'!D:D,B31) -> 0 | F31: =D31-E31 -> 800 | G31: =IF(D31=0,IF(E31=0,0,9.99),E31/D31) -> 0
A32: Alimentação | B32: Feira | D32: =VLOOKUP(B32,Config!$E$11:$F$50,2,FALSE()) -> 180 | E32: =SUMIFS('Lançamentos'!C:C,'Lançamentos'!B:B,"Despesa",'Lançamentos'!A:A,">="&$B$4,'Lançamentos'!A:A,"<="&$D$4,'Lançamentos'!D:D,B32) -> 0 | F32: =D32-E32 -> 180 | G32: =IF(D32=0,IF(E32=0,0,9.99),E32/D32) -> 0
A33: Alimentação | B33: Açougue/padaria | D33: =VLOOKUP(B33,Config!$E$11:$F$50,2,FALSE()) -> 250 | E33: =SUMIFS('Lançamentos'!C:C,'Lançamentos'!B:B,"Despesa",'Lançamentos'!A:A,">="&$B$4,'Lançamentos'!A:A,"<="&$D$4,'Lançamentos'!D:D,B33) -> 0 | F33: =D33-E33 -> 250 | G33: =IF(D33=0,IF(E33=0,0,9.99),E33/D33) -> 0
A34: Alimentação | B34: Delivery | D34: =VLOOKUP(B34,Config!$E$11:$F$50,2,FALSE()) -> 280 | E34: =SUMIFS('Lançamentos'!C:C,'Lançamentos'!B:B,"Despesa",'Lançamentos'!A:A,">="&$B$4,'Lançamentos'!A:A,"<="&$D$4,'Lançamentos'!D:D,B34) -> 0 | F34: =D34-E34 -> 280 | G34: =IF(D34=0,IF(E34=0,0,9.99),E34/D34) -> 0
A35: Alimentação | B35: Restaurante casal | D35: =VLOOKUP(B35,Config!$E$11:$F$50,2,FALSE()) -> 150 | E35: =SUMIFS('Lançamentos'!C:C,'Lançamentos'!B:B,"Despesa",'Lançamentos'!A:A,">="&$B$4,'Lançamentos'!A:A,"<="&$D$4,'Lançamentos'!D:D,B35) -> 0 | F35: =D35-E35 -> 150 | G35: =IF(D35=0,IF(E35=0,0,9.99),E35/D35) -> 0
A36: Alimentação | B36: Padaria/café (semana) | D36: =VLOOKUP(B36,Config!$E$11:$F$50,2,FALSE()) -> 100 | E36: =SUMIFS('Lançamentos'!C:C,'Lançamentos'!B:B,"Despesa",'Lançamentos'!A:A,">="&$B$4,'Lançamentos'!A:A,"<="&$D$4,'Lançamentos'!D:D,B36) -> 0 | F36: =D36-E36 -> 100 | G36: =IF(D36=0,IF(E36=0,0,9.99),E36/D36) -> 0
A37: Alimentação | B37: Lanches esporádicos | D37: =VLOOKUP(B37,Config!$E$11:$F$50,2,FALSE()) -> 60 | E37: =SUMIFS('Lançamentos'!C:C,'Lançamentos'!B:B,"Despesa",'Lançamentos'!A:A,">="&$B$4,'Lançamentos'!A:A,"<="&$D$4,'Lançamentos'!D:D,B37) -> 19 | F37: =D37-E37 -> 41 | G37: =IF(D37=0,IF(E37=0,0,9.99),E37/D37) -> 0.31666667
... A63: Diversos | B63: Outros | D63: =VLOOKUP(B63,Config!$E$11:$F$50,2,FALSE()) -> 0 | E63: =SUMIFS('Lançamentos'!C:C,'Lançamentos'!B:B,"Despesa",'Lançamentos'!A:A,">="&$B$4,'Lançamentos'!A:A,"<="&$D$4,'Lançamentos'!D:D,B63) -> 0 | F63: =D63-E63 -> 0 | G63: =IF(D63=0,IF(E63=0,0,9.99),E63/D63) -> 0
A64: TOTAL | D64: =SUM(D26:D63) -> 8155 | E64: =SUM(E26:E63) -> 19 | F64: =D64-E64 -> 8136 | G64: =IF(D64=0,IF(E64=0,0,9.99),E64/D64) -> 0.002329859

Sheet Lançamentos
A1: LANÇAMENTOS — DIA A DIA
A3: 💡 Dicas: Ctrl+; insere data de hoje • Categoria/Pagador/Fonte têm dropdown (toque e escolha) • 1 lançamento por gasto avulso, 1 por semana para "Miúdos" e "Cuidado pessoal"
A5: Data | B5: Tipo | C5: Valor | D5: Categoria | E5: Pagador | F5: Fonte | G5: Descrição
G6: Mcdonalds
A7: 46136.091 | B7: Despesa | C7: 19 | D7: Lanches esporádicos | E7: Gustavo | F7: Outro

Sheet Orçamento Mensal
A1: ORÇAMENTO MENSAL — GUSTAVO & LUANA
A3: RENDA MENSAL
A4: Categoria | B4: Valor | C4: % da Renda | D4: Observação
A5: Salário Gustavo (sem auxílios) | B5: 2200 | C5: =B5/$B$9 -> 0.25287356 | D5: Salário base (R$ 3.400 - R$ 1.200 aux combustível)
A6: Auxílio combustível Gustavo | B6: 1200 | C6: =B6/$B$9 -> 0.13793103 | D6: Recebido em folha, usado para moto + sobra livre
A7: VR/VA Gustavo (alimentação) | B7: 1500 | C7: =B7/$B$9 -> 0.17241379 | D7: MARCADO — apenas alimentação (cartão)
A8: Salário Luana | B8: 3800 | C8: =B8/$B$9 -> 0.43678161 | D8: Luana tem café e almoço grátis no trabalho
A9: RENDA TOTAL | B9: =SUM(B5:B8) -> 8700 | C9: 1
A11: GASTOS FIXOS (obrigatórios)
A12: Categoria | B12: Valor | C12: % da Renda | D12: Observação
A13: Financiamento Caixa (casa) | B13: 1910 | C13: =B13/$B$9 -> 0.21954023 | D13: Parcela atual — cresce pouco (TR baixa)
A14: Financiamento Vasco (entrada) | B14: 870 | C14: =B14/$B$9 -> 0.1 | D14: Cresce ~R$ 12/mês (IPCA + 1% a.m.)
A15: Combustível moto Gustavo | B15: 145 | C15: =B15/$B$9 -> 0.016666667 | D15: Gasolina mensal
A16: Óleo moto (provisão) | B16: 75 | C16: =B16/$B$9 -> 0.0086206897 | D16: R$ 150 a cada 2 meses
A17: Uber Luana (trabalho) | B17: 200 | C17: =B17/$B$9 -> 0.022988506 | D17: ~R$ 10/dia ida, Gustavo busca à tarde
A18: TOTAL FIXOS | B18: =SUM(B13:B17) -> 3200 | C18: =B18/$B$9 -> 0.36781609
A20: ALIMENTAÇÃO
A21: Categoria | B21: Valor | C21: % da Renda | D21: Observação
A22: Supermercado mensal | B22: 800 | C22: =B22/$B$9 -> 0.091954023 | D22: Pago com VR/VA — fazer compra grande 1x/mês + reposição
A23: Feira (hortifruti) | B23: 180 | C23: =B23/$B$9 -> 0.020689655 | D23: VR/VA — feira CEASA ou bairro (mais barato)
A24: Açougue/padaria | B24: 250 | C24: =B24/$B$9 -> 0.028735632 | D24: VR/VA — açougue de bairro (20-30% mais barato)
A25: Padaria/café manhã fora | B25: 100 | C25: =B25/$B$9 -> 0.011494253 | D25: VR/VA — limite combinado 2 pessoas
A26: Delivery planejado (1x/sem) | B26: 280 | C26: =B26/$B$9 -> 0.032183908 | D26: ⚠ CATEGORIA PROBLEMA — 1 pedido/semana
A27: Saída casal restaurante (1x/mês) | B27: 150 | C27: =B27/$B$9 -> 0.017241379 | D27: ⚠ 1 jantar caprichado por mês
A28: Lanches/cafeteria esporádicos | B28: 60 | C28: =B28/$B$9 -> 0.0068965517 | D28: ⚠ Folga para imprevistos
A29: TOTAL ALIMENTAÇÃO | B29: =SUM(B22:B28) -> 1820 | C29: =B29/$B$9 -> 0.2091954
A31: ASSINATURAS E TECNOLOGIA
A32: Categoria | B32: Valor | C32: % da Renda | D32: Observação
A33: Celular 2 linhas (plano controle) | B33: 100 | C33: =B33/$B$9 -> 0.011494253 | D33: TIM/Vivo/Claro Controle ~25GB cada
A34: Internet fibra 200 Mbps (quando mudar) | B34: 100 | C34: =B34/$B$9 -> 0.011494253 | D34: Suficiente para streaming + home office
A35: Streaming vídeo 1 principal + 1 rotativo | B35: 75 | C35: =B35/$B$9 -> 0.0086206897 | D35: Ex: Netflix fixo + Max/Prime/Disney alternando
A36: Spotify Duo (2 contas) | B36: 28 | C36: =B36/$B$9 -> 0.0032183908 | D36: Substituir se só 1 usa
A37: Google One 200GB (compartilhado) | B37: 17 | C37: =B37/$B$9 -> 0.001954023 | D37: Backup de fotos e arquivos
A38: TOTAL ASSINATURAS | B38: =SUM(B33:B37) -> 320 | C38: =B38/$B$9 -> 0.036781609
A40: CONTAS DA CASA (APÓS MUDANÇA)
A41: Categoria | B41: Valor | C41: % da Renda | D41: Observação
A42: Condomínio Villaggio Blu | B42: 500 | C42: =B42/$B$9 -> 0.057471264 | D42: Estimativa — confirmar em assembleia
A43: Luz | B43: 170 | C43: =B43/$B$9 -> 0.01954023 | D43: Casal, casa 54m², chuveiro a gás
A44: Água (rateada — sem medidor ind.) | B44: 80 | C44: =B44/$B$9 -> 0.0091954023 | D44: Ver Cláusula 6 item 8 do contrato
A45: Gás encanado | B45: 55 | C45: =B45/$B$9 -> 0.0063218391 | D45: Chuveiro + fogão + aquecedor
...

Sheet Compras da Casa
A1: PLANO DE COMPRAS — MONTAGEM DA CASA
A3: Reserva disponível: R$ 17.000 (CDB 115% CDI)
A5: Tier | B5: Item | C5: Valor Mín | D5: Valor Máx | E5: Planejado | F5: Forma Pagto | G5: Observação
A6: T1 | B6: Aquecedor de passagem a gás | C6: 800 | D6: 1400 | E6: 1000 | F6: PIX | G6: Komeco/Rinnai 11L usado 1-2 anos OLX = 40% desconto
A7: T1 | B7: Duchas Lorenzetti Advanced (x2) | C7: 300 | D7: 600 | E7: 450 | F7: PIX | G7: Básica, boa qualidade, não exageram
A8: T1 | B8: Geladeira Frost Free 340L (se não têm) | C8: 2500 | D8: 3800 | E8: 3000 | F8: Cartão 10x | G8: Electrolux/Brastemp — considerar usada 2-3 anos
A9: T1 | B9: Fogão 4 bocas a gás (se não têm) | C9: 1200 | D9: 2000 | E9: 1500 | F9: Cartão 10x | G9: Atlas/Itatiaia suficientes — não precisa 5 bocas
A10: T1 | B10: Máquina de lavar 11kg (se não têm) | C10: 1800 | D10: 3000 | E10: 2200 | F10: Cartão 10x | G10: Brastemp Ative básica ou Electrolux usada
A11: T1 | B11: Pequenos essenciais (lâmpadas, tomadas, ferragens) | C11: 400 | D11: 700 | E11: 500 | F11: PIX | G11: Lâmpadas LED, tomadas extras, pendurar TV
A12: T2 | B12: Pressurizador Rowa/Komeco | C12: 600 | D12: 1200 | E12: 800 | F12: PIX | G12: Necessário pela pressão baixa do condomínio
A13: T2 | B13: Filtros caixa d'água (entrada + torneira) | C13: 400 | D13: 800 | E13: 500 | F13: PIX | G13: Filtro central + filtros pontuais
A14: T2 | B14: Cortinas/persianas essenciais (sala + 2 quartos) | C14: 500 | D14: 1000 | E14: 700 | F14: Cartão 5x | G14: Começar só com o necessário, não todas janelas
A15: T2 | B15: Rack TV + suporte de parede | C15: 300 | D15: 600 | E15: 400 | F15: Cartão 5x | G15: Suporte articulado bom vale a pena
A16: T3 | B16: TV 50-55" 4K | C16: 2000 | D16: 3500 | E16: 2500 | F16: Aguardar BF | G16: ESPERAR Black Friday novembro — economia 20-30%
A17: T3 | B17: Ar-condicionado split 9000 BTUs (instalado) | C17: 2500 | D17: 3800 | E17: 3000 | F17: Aguardar verão | G17: ESPERAR — só comprar se verão apertar
A18: T3 | B18: Piso laminado 2 quartos (~17m²) | C18: 1500 | D18: 2800 | E18: 0 | F18: POSTERGAR | G18: NÃO COMPRAR AGORA — morar primeiro, avaliar
B19: TOTAL PLANEJADO | C19: =SUM(C6:C18) -> 14800 | D19: =SUM(D6:D18) -> 25200 | E19: =SUM(E6:E18) -> 16550
B20: RESERVA DISPONÍVEL | E20: 17000
B21: SOBRA DA RESERVA (proteção) | E21: =E20-E19 -> 450 | G21: Manter para imprevistos pós-mudança
A24: ESTRATÉGIA DE PAGAMENTO
A25: REGRA 1 | B25: Parcelas somadas no cartão (comprometimento futuro) ≤ R$ 720/mês (10% renda)
A26: REGRA 2 | B26: Desconto PIX > 5% → pagar PIX sempre (ganha mais que 115% CDI)
A27: REGRA 3 | B27: Desconto PIX < 3% → parcelar sem juros (mantém dinheiro rendendo no CDB)
A28: REGRA 4 | B28: CDB 115% CDI rende ~14% a.a. → parcelar 10x sem juros ganha ~R$ 115 por R$ 1000
A29: REGRA 5 | B29: Nunca parcelar 3 compras grandes no mesmo mês — diluir no tempo
A30: REGRA 6 | B30: Antes de cada compra grande, verificar "próximas faturas" do cartão

Sheet Metas de Poupança
A1: METAS DE POUPANÇA E PROGRESSO
A3: PARÂMETROS (edite as células azuis)
A4: Poupança mensal (CDB 115% CDI) | B4: 700 | D4: Valor transferido mensalmente da conta para o CDB
A5: Custo mensal básico (sobrevivência) | B5: 3500 | D5: Soma de contas essenciais caso tudo dê errado
A6: Meta reserva emergência (6x custos) | B6: =B5*6 -> 21000 | D6: Meta: sobreviver 6 meses sem renda
A7: Rendimento esperado CDB (% ano) | B7: 0.141 | D7: 120% CDI até R$ 10k + 115% CDI acima (média ~14,1%)
A9: PROJEÇÃO DE ACÚMULO (sem considerar rendimento)
A10: Mês | B10: Acumulado | C10: % Meta | D10: Marco
A11: Mês 1 | B11: =$B$4*(((1+$B$7/12)^1-1)/($B$7/12)) -> 700 | C11: =B11/$B$6 -> 0.033333333
A12: Mês 2 | B12: =$B$4*(((1+$B$7/12)^2-1)/($B$7/12)) -> 1408.225 | C12: =B12/$B$6 -> 0.067058333
A13: Mês 3 | B13: =$B$4*(((1+$B$7/12)^3-1)/($B$7/12)) -> 2124.7716 | C13: =B13/$B$6 -> 0.1011796 | D13: 3 meses — começando
A14: Mês 4 | B14: =$B$4*(((1+$B$7/12)^4-1)/($B$7/12)) -> 2849.7377 | C14: =B14/$B$6 -> 0.1357018
A15: Mês 5 | B15: =$B$4*(((1+$B$7/12)^5-1)/($B$7/12)) -> 3583.2221 | C15: =B15/$B$6 -> 0.17062963
A16: Mês 6 | B16: =$B$4*(((1+$B$7/12)^6-1)/($B$7/12)) -> 4325.325 | C16: =B16/$B$6 -> 0.20596786 | D16: Meio ano — hábito criado
A17: Mês 7 | B17: =$B$4*(((1+$B$7/12)^7-1)/($B$7/12)) -> 5076.1476 | C17: =B17/$B$6 -> 0.24172131
A18: Mês 8 | B18: =$B$4*(((1+$B$7/12)^8-1)/($B$7/12)) -> 5835.7923 | C18: =B18/$B$6 -> 0.27789487
A19: Mês 9 | B19: =$B$4*(((1+$B$7/12)^9-1)/($B$7/12)) -> 6604.3629 | C19: =B19/$B$6 -> 0.31449347
A20: Mês 10 | B20: =$B$4*(((1+$B$7/12)^10-1)/($B$7/12)) -> 7381.9641 | C20: =B20/$B$6 -> 0.3515221
A21: Mês 11 | B21: =$B$4*(((1+$B$7/12)^11-1)/($B$7/12)) -> 8168.7022 | C21: =B21/$B$6 -> 0.38898582
A22: Mês 12 | B22: =$B$4*(((1+$B$7/12)^12-1)/($B$7/12)) -> 8964.6844 | C22: =B22/$B$6 -> 0.42688974 | D22: 1 ano — 1ª grande revisão
A23: Mês 13 | B23: =$B$4*(((1+$B$7/12)^13-1)/($B$7/12)) -> 9770.0195 | C23: =B23/$B$6 -> 0.46523902
A24: Mês 14 | B24: =$B$4*(((1+$B$7/12)^14-1)/($B$7/12)) -> 10584.817 | C24: =B24/$B$6 -> 0.50403891
A25: Mês 15 | B25: =$B$4*(((1+$B$7/12)^15-1)/($B$7/12)) -> 11409.189 | C25: =B25/$B$6 -> 0.54329471
A26: Mês 16 | B26: =$B$4*(((1+$B$7/12)^16-1)/($B$7/12)) -> 12243.247 | C26: =B26/$B$6 -> 0.58301175
A27: Mês 17 | B27: =$B$4*(((1+$B$7/12)^17-1)/($B$7/12)) -> 13087.105 | C27: =B27/$B$6 -> 0.62319547
A28: Mês 18 | B28: =$B$4*(((1+$B$7/12)^18-1)/($B$7/12)) -> 13940.878 | C28: =B28/$B$6 -> 0.66385135 | D28: Deve ter ~R$ 12k acumulados
A29: Mês 19 | B29: =$B$4*(((1+$B$7/12)^19-1)/($B$7/12)) -> 14804.684 | C29: =B29/$B$6 -> 0.70498494
A30: Mês 20 | B30: =$B$4*(((1+$B$7/12)^20-1)/($B$7/12)) -> 15678.639 | C30: =B30/$B$6 -> 0.74660185
A31: Mês 21 | B31: =$B$4*(((1+$B$7/12)^21-1)/($B$7/12)) -> 16562.863 | C31: =B31/$B$6 -> 0.78870775
A32: Mês 22 | B32: =$B$4*(((1+$B$7/12)^22-1)/($B$7/12)) -> 17457.476 | C32: =B32/$B$6 -> 0.8313084
A33: Mês 23 | B33: =$B$4*(((1+$B$7/12)^23-1)/($B$7/12)) -> 18362.602 | C33: =B33/$B$6 -> 0.87440961
A34: Mês 24 | B34: =$B$4*(((1+$B$7/12)^24-1)/($B$7/12)) -> 19278.362 | C34: =B34/$B$6 -> 0.91801725 | D34: 2 anos — deve estar perto da meta
A35: Mês 25 | B35: =$B$4*(((1+$B$7/12)^25-1)/($B$7/12)) -> 20204.883 | C35: =B35/$B$6 -> 0.96213729
A36: Mês 26 | B36: =$B$4*(((1+$B$7/12)^26-1)/($B$7/12)) -> 21142.29 | C36: =B36/$B$6 -> 1.0067757
A37: Mês 27 | B37: =$B$4*(((1+$B$7/12)^27-1)/($B$7/12)) -> 22090.712 | C37: =B37/$B$6 -> 1.0519387
A38: Mês 28 | B38: =$B$4*(((1+$B$7/12)^28-1)/($B$7/12)) -> 23050.278 | C38: =B38/$B$6 -> 1.0976323
A39: Mês 29 | B39: =$B$4*(((1+$B$7/12)^29-1)/($B$7/12)) -> 24021.119 | C39: =B39/$B$6 -> 1.1438628
A40: Mês 30 | B40: =$B$4*(((1+$B$7/12)^30-1)/($B$7/12)) -> 25003.367 | C40: =B40/$B$6 -> 1.1906365 | D40: Possivelmente meta alcançada
A41: Mês 31 | B41: =$B$4*(((1+$B$7/12)^31-1)/($B$7/12)) -> 25997.157 | C41: =B41/$B$6 -> 1.2379598
A42: Mês 32 | B42: =$B$4*(((1+$B$7/12)^32-1)/($B$7/12)) -> 27002.623 | C42: =B42/$B$6 -> 1.2858392
...

Sheet Config
A1: CONFIG — PARÂMETROS E LISTAS (editar aqui)
A3: Parâmetros ajustáveis (editar células azuis)
A4: Salário Luana (base) | B4: ='Orçamento Mensal'!B8 -> 3800 | C4: Valor que ela recebe mensal (puxa do Orçamento)
A5: Reserva pessoal Luana (mês) | B5: 0 | C5: Quanto ela separa pra projetos pessoais antes de transferir
A6: Mês de referência (qualquer dia do mês) | B6: =TODAY() -> 46136 | C6: Mude se quiser analisar outro mês no Dashboard
A9: Listas (usadas nos dropdowns de Lançamentos)
A10: Tipo | B10: Pagador | C10: Fonte | D10: Grupo | E10: Categoria (Despesa) | F10: Planejado (R$/mês) | H10: Grupo | I10: Categoria (Receita) | J10: Planejado (R$/mês) | L10: Todas Categorias
A11: Despesa | B11: Gustavo | C11: Conta Gustavo | D11: Fixos | E11: Financ. Caixa | F11: ='Orçamento Mensal'!B13 -> 1910 | H11: Receita | I11: Salário Gustavo | J11: ='Orçamento Mensal'!B5 -> 2200 | L11: Financ. Caixa
A12: Receita | B12: Luana | C12: Conta Luana | D12: Fixos | E12: Financ. Vasco | F12: ='Orçamento Mensal'!B14 -> 870 | H12: Receita | I12: Auxílio Combustível | J12: ='Orçamento Mensal'!B6 -> 1200 | L12: Financ. Vasco
C13: Cartão Gustavo | D13: Fixos | E13: Combustível moto | F13: ='Orçamento Mensal'!B15 -> 145 | H13: Receita | I13: VR/VA Gustavo | J13: ='Orçamento Mensal'!B7 -> 1500 | L13: Combustível moto
C14: Cartão Luana | D14: Fixos | E14: Óleo moto (provisão) | F14: ='Orçamento Mensal'!B16 -> 75 | H14: Receita | I14: Salário Luana | J14: ='Orçamento Mensal'!B8 -> 3800 | L14: Óleo moto (provisão)
C15: VR/VA Gustavo | D15: Fixos | E15: Uber Luana | F15: ='Orçamento Mensal'!B17 -> 200 | H15: Receita | I15: Renda extra | J15: =0 -> 0 | L15: Uber Luana
C16: Aux. Combustível Gustavo | D16: Alimentação | E16: Supermercado | F16: ='Orçamento Mensal'!B22 -> 800 | L16: Supermercado
C17: Dinheiro | D17: Alimentação | E17: Feira | F17: ='Orçamento Mensal'!B23 -> 180 | L17: Feira
C18: Folha (crédito em conta) | D18: Alimentação | E18: Açougue/padaria | F18: ='Orçamento Mensal'!B24 -> 250 | L18: Açougue/padaria
C19: Outro | D19: Alimentação | E19: Delivery | F19: ='Orçamento Mensal'!B26 -> 280 | L19: Delivery
D20: Alimentação | E20: Restaurante casal | F20: ='Orçamento Mensal'!B27 -> 150 | L20: Restaurante casal
D21: Alimentação | E21: Padaria/café (semana) | F21: ='Orçamento Mensal'!B25 -> 100 | L21: Padaria/café (semana)
D22: Alimentação | E22: Lanches esporádicos | F22: ='Orçamento Mensal'!B28 -> 60 | L22: Lanches esporádicos
D23: Assinaturas | E23: Celular | F23: ='Orçamento Mensal'!B33 -> 100 | L23: Celular
D24: Assinaturas | E24: Internet | F24: ='Orçamento Mensal'!B34 -> 100 | L24: Internet
D25: Assinaturas | E25: Streaming | F25: ='Orçamento Mensal'!B35 -> 75 | L25: Streaming
D26: Assinaturas | E26: Spotify | F26: ='Orçamento Mensal'!B36 -> 28 | L26: Spotify
D27: Assinaturas | E27: Google One | F27: ='Orçamento Mensal'!B37 -> 17 | L27: Google One
D28: Casa | E28: Condomínio | F28: ='Orçamento Mensal'!B42 -> 500 | L28: Condomínio
D29: Casa | E29: Luz | F29: ='Orçamento Mensal'!B43 -> 170 | L29: Luz
D30: Casa | E30: Água | F30: ='Orçamento Mensal'!B44 -> 80 | L30: Água
D31: Casa | E31: Gás | F31: ='Orçamento Mensal'!B45 -> 55 | L31: Gás
D32: Casa | E32: IPTU (provisão) | F32: ='Orçamento Mensal'!B46 -> 60 | L32: IPTU (provisão)
D33: Saúde | E33: Plano Unimed Gustavo | F33: ='Orçamento Mensal'!B51 -> 60 | L33: Plano Unimed Gustavo
D34: Saúde | E34: Plano Amil Luana | F34: ='Orçamento Mensal'!B52 -> 60 | L34: Plano Amil Luana
D35: Saúde | E35: Coparticipação médica | F35: ='Orçamento Mensal'!B53 -> 120 | L35: Coparticipação médica
D36: Saúde | E36: Farmácia | F36: ='Orçamento Mensal'!B54 -> 80 | L36: Farmácia
D37: Saúde | E37: Dentista | F37: ='Orçamento Mensal'!B55 -> 50 | L37: Dentista
D38: Saúde | E38: Cuidado pessoal (semana) | F38: ='Orçamento Mensal'!B56 -> 120 | L38: Cuidado pessoal (semana)
D39: Lazer | E39: Roupas | F39: ='Orçamento Mensal'!B61 -> 120 | L39: Roupas
D40: Lazer | E40: Peças íntimas | F40: ='Orçamento Mensal'!B62 -> 50 | L40: Peças íntimas
D41: Lazer | E41: Calçado | F41: ='Orçamento Mensal'!B63 -> 60 | L41: Calçado
D42: Lazer | E42: Rolê casal | F42: ='Orçamento Mensal'!B64 -> 150 | L42: Rolê casal
D43: Lazer | E43: Presentes | F43: ='Orçamento Mensal'!B65 -> 80 | L43: Presentes
...
